Workbook
Name nilan: 'Master Data'!$A$787
Name nolan: 'Master Data'!$B$788

Sheet Master Data
A1: Master Liste - Salsaflow Dance Company
A3: Mobile | B3: Vorname | C3: Name | D3: m/w | E3: Tarif | F3: Email | G3: Adresse | H3: Postleitzahl | I3: Quelle
A4: 0764032801 | B4: Adrian | C4: Bartella | F4: adrian.bartella@gmx.net | G4: stadthausgasse 15 | H4: 4051 Basel
A5: 0786855151 | B5: Adrian | C5: Baumeyer | F5: adrian.baumeyer@gmail.com | G5: Belchenring 53 | H5: 4123 Allschwil
B6: Aglaia | C6: Graf | F6: aglaiagraf@gmx.ch | G6: stadthausgasse 16 | H6: 4052 Basel
A7: 0765598635 | B7: alberto | C7: iannicca | F7: alberto.iannicca@gmx.ch | G7: Belchenring 54 | H7: 4124 Allschwil
A8: 0796882436 | B8: Aldiana | C8: Mazza | F8: aldiana.mazza@bluewin.ch | G8: stadthausgasse 17 | H8: 4053 Basel
A9: 0796191628 | B9: Aleksandra | C9: Heinrich | F9: aleksandra.heinrich@gmail.com | G9: Belchenring 55 | H9: 4125 Allschwil
A10: 0787964480 | B10: Alessandra | C10: Carlino | F10: a.carlino@gmx.ch | G10: stadthausgasse 18 | H10: 4054 Basel
A11: 0796647491 | B11: Aletta | C11: Kuhn | F11: aletta.kuhn@gmail.com | G11: Belchenring 56 | H11: 4126 Allschwil
A12: 0786861893 | B12: Alexander | C12: Dieter | F12: alex_dieter@hotmail.com | G12: stadthausgasse 19 | H12: 4055 Basel
A13: 0797848703 | B13: Alexander | C13: Fuentes | F13: fuental@gmx.net | G13: Belchenring 57 | H13: 4127 Allschwil
A14: 0033611926373 | B14: Alexandra | C14: Molnar | F14: Al-ex.m@hotmail.fr | G14: stadthausgasse 20 | H14: 4056 Basel
A15: 0794648772 | B15: Alexandra | C15: Bunge | F15: alexandrabunge@bluewin.ch | G15: Belchenring 58 | H15: 4128 Allschwil
A16: 0792673275 | B16: Alexandra | C16: Plattner | F16: alexandra.plattner@hotmail.com | G16: stadthausgasse 21 | H16: 4057 Basel
A17: 0792227006 | B17: Alexandra | C17: Jenal | F17: Alexandra.jenal@gmail.com | G17: Belchenring 59 | H17: 4129 Allschwil
A18: 0797801501 | B18: Alexandra | C18: Siegenthaler | F18: a.siegenthaler@hotmail.com | G18: stadthausgasse 22 | H18: 4058 Basel
... A21: 0791201078 | B21: Alicia | C21: Kerbrat | F21: shoupi4@hotmail.com | G21: Belchenring 61 | H21: 4131 Allschwil
B22: Alison | C22: Lamb | F22: alison.lamb@roche.com | G22: stadthausgasse 24 | H22: 4060 Basel
A23: 0795453654 | B23: Alma | C23: Voser | F23: alma_voser@yahoo.de | G23: Belchenring 62 | H23: 4132 Allschwil
A24: 0787050829 | B24: Amanda | C24: Scott | F24: amandaes@hotmail.com | G24: stadthausgasse 25 | H24: 4061 Basel
A25: 0795978220 | B25: Ana | C25: da Silva Correia | F25: anadsc@gmail.com | G25: Belchenring 63 | H25: 4133 Allschwil
A26: 0787171226 | B26: Ana | C26: Morales | F26: anaestermorales@ymail.com | G26: stadthausgasse 26 | H26: 4062 Basel
A27: 0799543183 | B27: Ana | C27: Lopes | F27: alopes.rust@gmail.com | G27: Belchenring 64 | H27: 4134 Allschwil
B28: Ana Maria | C28: Carrillo | F28: anica1979@hotmail.com | G28: stadthausgasse 27 | H28: 4063 Basel
A29: 0797506526 | B29: Andi | C29: Meier | F29: and_meier@hotmail.com | G29: stadthausgasse 28 | H29: 4064 Basel
A30: 0017221892089 | B30: Andrea | C30: Theis | F30: andrea_theis@yahoo.de | G30: Belchenring 66 | H30: 4136 Allschwil
B31: Andrea | C31: Häberlin | F31: ahaeberlin@gmx.ch | G31: stadthausgasse 29 | H31: 4065 Basel
B32: Andrea | C32: Schäfer | F32: andrea.schaefer@gmx.ch | G32: Belchenring 67 | H32: 4137 Allschwil
A33: 0765062732 | B33: Andrea | C33: Schmitter | F33: andrea.schmitter@hotmail.com | G33: stadthausgasse 30 | H33: 4066 Basel
A34: 0491774479811 | B34: Andrea | C34: Collatz | F34: andreacollatz@gmx.de | G34: Belchenring 68 | H34: 4138 Allschwil
A35: 0774549009 | B35: Annina | C35: Stooss | F35: Annina@stooss.ch | G35: stadthausgasse 31 | H35: 4067 Basel
A36: 0763270815 | B36: Annina | C36: Striebel | F36: a.striebel@gmx.ch | G36: Belchenring 69 | H36: 4139 Allschwil
A37: 0787731548 | B37: Antonio / Desirée | C37: Perla | F37: a.perla@bluewin.ch | G37: stadthausgasse 32 | H37: 4068 Basel
A38: 0767759451 | B38: Araceli | C38: Lamelas Cabello | F38: araceli.lamelas@unibas.ch | G38: Belchenring 70 | H38: 4140 Allschwil
A39: 0796680215 | B39: Armin | C39: Barandun | F39: arminbarandun@datacomm.ch | G39: stadthausgasse 33 | H39: 4069 Basel
A40: 0786768889 | B40: Arun (männlich) | C40: Wadhawan | F40: poloarun@yahoo.com | G40: Belchenring 71 | H40: 4141 Allschwil
A41: 0797070796 | B41: Astrid | C41: Zubler | F41: astrid.zubler@bluewin.ch | G41: stadthausgasse 34 | H41: 4070 Basel
B42: Astrid | C42: Fink | F42: juerg.fink@bluewin.ch | G42: Belchenring 72 | H42: 4142 Allschwil
A43: 0793867737 | B43: Atiya | C43: Özkaya | F43: atiya_oezkaya@hotmail.com | G43: stadthausgasse 35 | H43: 4071 Basel
...

Sheet Mo_Salsa Intermediate Stufe 11
A1: Anmeldungen - Salsa Intermediate Stufe 11
A3: Datum: | B3: 05.01.2026 - 02.03.2026 | D3: Kurstag: | E3: Montag | G3: Lehrer: | H3: Viviana & Sebastian
A4: Zeit: | B4: 18:30 - 19:30 | D4: Ort: | E4: Elisabethenanlage 7 | G4: Preis: | H4: CHF 190.- / CHF 160.-
A6: Vorname | B6: Name | C6: E-Mail | D6: Mobile | E6: Bemerkungen | F6: m/w | G6: Tarif | H6: Betrag | I6: Anwesenheit
A7: =VLOOKUP(D7,'Master Data'!A:F,2,FALSE) -> Dominik | B7: =VLOOKUP(D7,'Master Data'!A:F,3,FALSE) -> Mann | C7: =VLOOKUP(D7,'Master Data'!A:F,6,FALSE) -> dominik.mann@icloud.com | D7: 0795694012 | F7: =VLOOKUP(D7,'Master Data'!A:F,4,FALSE) -> m | G7: =VLOOKUP(D7,'Master Data'!A:F,5,FALSE) -> Normal | H7: 160 | I7: X | J7: - | K7: X | L7: - | M7: X
A8: =VLOOKUP(D8,'Master Data'!A:F,2,FALSE) -> Daniel | B8: =VLOOKUP(D8,'Master Data'!A:F,3,FALSE) -> Hoffmann | C8: =VLOOKUP(D8,'Master Data'!A:F,6,FALSE) -> daniel.pascal.hoffmann@gmail.com | D8: 0765055780 | F8: =VLOOKUP(D8,'Master Data'!A:F,4,FALSE) -> m | G8: =VLOOKUP(D8,'Master Data'!A:F,5,FALSE) -> Normal | H8: 240 | I8: X | J8: X | K8: X | M8: X
A9: =VLOOKUP(D9,'Master Data'!A:F,2,FALSE) -> Selina | B9: =VLOOKUP(D9,'Master Data'!A:F,3,FALSE) -> Schenker | C9: =VLOOKUP(D9,'Master Data'!A:F,6,FALSE) -> selina.schenker@live.de | D9: 0793283745 | F9: =VLOOKUP(D9,'Master Data'!A:F,4,FALSE) -> w | G9: =VLOOKUP(D9,'Master Data'!A:F,5,FALSE) -> Normal | H9: 240 | I9: X | J9: X | K9: X | M9: X
A10: =VLOOKUP(D10,'Master Data'!A:F,2,FALSE) -> Onur | B10: =VLOOKUP(D10,'Master Data'!A:F,3,FALSE) -> Erdem | C10: =VLOOKUP(D10,'Master Data'!A:F,6,FALSE) -> erdem-onur@hotmail.com | D10: 0786111634 | F10: =VLOOKUP(D10,'Master Data'!A:F,4,FALSE) -> m | G10: =VLOOKUP(D10,'Master Data'!A:F,5,FALSE) -> Normal | I10: X | J10: X | K10: X | M10: X
A11: =VLOOKUP(D11,'Master Data'!A:F,2,FALSE) -> Alexandra | B11: =VLOOKUP(D11,'Master Data'!A:F,3,FALSE) -> Daniel | C11: =VLOOKUP(D11,'Master Data'!A:F,6,FALSE) -> danielalexandra970@gmail.com | D11: 0768150705 | F11: =VLOOKUP(D11,'Master Data'!A:F,4,FALSE) -> w | G11: =VLOOKUP(D11,'Master Data'!A:F,5,FALSE) -> Paar | H11: 160 | I11: X | J11: X | K11: X | M11: X
A12: =VLOOKUP(D12,'Master Data'!A:F,2,FALSE) -> Laszlo | B12: =VLOOKUP(D12,'Master Data'!A:F,3,FALSE) -> Lukacs | C12: =VLOOKUP(D12,'Master Data'!A:F,6,FALSE) -> laci91128@gmail.com | D12: 0036703794124 | F12: =VLOOKUP(D12,'Master Data'!A:F,4,FALSE) -> m | G12: =VLOOKUP(D12,'Master Data'!A:F,5,FALSE) -> Normal | H12: 410 | I12: - | J12: X | K12: X | M12: X | N12: -
A13: =VLOOKUP(D13,'Master Data'!A:F,2,FALSE) -> Alicja | B13: =VLOOKUP(D13,'Master Data'!A:F,3,FALSE) -> Dziedzic | C13: =VLOOKUP(D13,'Master Data'!A:F,6,FALSE) -> alicja.dziedzic99@gmail.com | D13: 0779146940 | F13: =VLOOKUP(D13,'Master Data'!A:F,4,FALSE) -> w | G13: =VLOOKUP(D13,'Master Data'!A:F,5,FALSE) -> Normal | H13: 190 | I13: X | J13: X | K13: X | M13: X | O13: -
A14: =VLOOKUP(D14,'Master Data'!A:F,2,FALSE) -> Karolina | B14: =VLOOKUP(D14,'Master Data'!A:F,3,FALSE) -> Dziedzic | C14: =VLOOKUP(D14,'Master Data'!A:F,6,FALSE) -> kdziedzic09@gmail.com | D14: 0779507623 | F14: =VLOOKUP(D14,'Master Data'!A:F,4,FALSE) -> w | G14: =VLOOKUP(D14,'Master Data'!A:F,5,FALSE) -> Normal | H14: 285 | I14: X | J14: X | K14: X | M14: X | N14: -
A15: =VLOOKUP(D15,'Master Data'!A:F,2,FALSE) -> Lisa | B15: =VLOOKUP(D15,'Master Data'!A:F,3,FALSE) -> Velte | C15: =VLOOKUP(D15,'Master Data'!A:F,6,FALSE) -> lisa_velte@hotmail.com | D15: 0765703203 | F15: =VLOOKUP(D15,'Master Data'!A:F,4,FALSE) -> w | G15: =VLOOKUP(D15,'Master Data'!A:F,5,FALSE) -> Normal | H15: 190 | I15: - | J15: X | K15: - | M15: X | N15: - | P15: -
A16: =VLOOKUP(D16,'Master Data'!A:F,2,FALSE) -> Marina | B16: =VLOOKUP(D16,'Master Data'!A:F,3,FALSE) -> Despotovic | C16: =VLOOKUP(D16,'Master Data'!A:F,6,FALSE) -> marina.despotovic@gmx.ch | D16: 0797907059 | F16: =VLOOKUP(D16,'Master Data'!A:F,4,FALSE) -> w | G16: =VLOOKUP(D16,'Master Data'!A:F,5,FALSE) -> Normal | H16: 190 | I16: - | J16: X | K16: X | M16: X
A17: =VLOOKUP(D17,'Master Data'!A:F,2,FALSE) -> Nikola | B17: =VLOOKUP(D17,'Master Data'!A:F,3,FALSE) -> Jevtic | C17: =VLOOKUP(D17,'Master Data'!A:F,6,FALSE) -> nikola.jevtic@bluewin.ch | D17: 0796971944 | F17: =VLOOKUP(D17,'Master Data'!A:F,4,FALSE) -> m | G17: =VLOOKUP(D17,'Master Data'!A:F,5,FALSE) -> Normal | H17: 285 | I17: X | J17: - | K17: X | M17: X
A18: =VLOOKUP(D18,'Master Data'!A:F,2,FALSE) -> Tobias | B18: =VLOOKUP(D18,'Master Data'!A:F,3,FALSE) -> Thommen | C18: =VLOOKUP(D18,'Master Data'!A:F,6,FALSE) -> tobithommen@hotmail.com | D18: 0798115348 | F18: =VLOOKUP(D18,'Master Data'!A:F,4,FALSE) -> m | G18: =VLOOKUP(D18,'Master Data'!A:F,5,FALSE) -> Normal | H18: 240 | I18: X | J18: - | K18: - | M18: X | N18: - | O18: -
A19: =VLOOKUP(D19,'Master Data'!A:F,2,FALSE) -> Myriam | B19: =VLOOKUP(D19,'Master Data'!A:F,3,FALSE) -> Aouadi | C19: =VLOOKUP(D19,'Master Data'!A:F,6,FALSE) -> aouadme@gmail.com | D19: 0795404172 | F19: =VLOOKUP(D19,'Master Data'!A:F,4,FALSE) -> w | G19: =VLOOKUP(D19,'Master Data'!A:F,5,FALSE) -> Normal | H19: 410 | I19: X | J19: X | K19: - | M19: X
A20: =VLOOKUP(D20,'Master Data'!A:F,2,FALSE) -> Burak | B20: =VLOOKUP(D20,'Master Data'!A:F,3,FALSE) -> Yildirim | C20: =VLOOKUP(D20,'Master Data'!A:F,6,FALSE) -> burak.yildirim@gmx.ch | D20: 0795584011 | F20: =VLOOKUP(D20,'Master Data'!A:F,4,FALSE) -> m | G20: =VLOOKUP(D20,'Master Data'!A:F,5,FALSE) -> Normal | I20: - | J20: X | K20: X | M20: X | O20: -
A21: =VLOOKUP(D21,'Master Data'!A:F,2,FALSE) -> Estelle | B21: =VLOOKUP(D21,'Master Data'!A:F,3,FALSE) -> Pierrot | C21: =VLOOKUP(D21,'Master Data'!A:F,6,FALSE) -> stella110@hotmail.fr | D21: 0765235926 | F21: =VLOOKUP(D21,'Master Data'!A:F,4,FALSE) -> w | G21: =VLOOKUP(D21,'Master Data'!A:F,5,FALSE) -> Normal | H21: 410 | I21: X | J21: X | K21: X | M21: X
A22: =VLOOKUP(D22,'Master Data'!A:F,2,FALSE) -> Malin | B22: =VLOOKUP(D22,'Master Data'!A:F,3,FALSE) -> Kirschke | C22: =VLOOKUP(D22,'Master Data'!A:F,6,FALSE) -> malin@m-kirschke.de | D22: 004915735499550 | F22: =VLOOKUP(D22,'Master Data'!A:F,4,FALSE) -> w | G22: =VLOOKUP(D22,'Master Data'!A:F,5,FALSE) -> Normal | H22: 190 | I22: - | J22: - | K22: - | M22: X | O22: - | P22: -
A23: =VLOOKUP(D23,'Master Data'!A:F,2,FALSE) -> Syria | B23: =VLOOKUP(D23,'Master Data'!A:F,3,FALSE) -> Savary | C23: =VLOOKUP(D23,'Master Data'!A:F,6,FALSE) -> syria.savary@hotmail.ch | D23: 0798724080 | F23: =VLOOKUP(D23,'Master Data'!A:F,4,FALSE) -> w | G23: =VLOOKUP(D23,'Master Data'!A:F,5,FALSE) -> Paar | H23: 340 | I23: X | J23: X | K23: X | L23: - | M23: X | N23: -
A24: =VLOOKUP(D24,'Master Data'!A:F,2,FALSE) -> Johanna | B24: =VLOOKUP(D24,'Master Data'!A:F,3,FALSE) -> Broschei | C24: =VLOOKUP(D24,'Master Data'!A:F,6,FALSE) -> jo.broschei@web.de | D24: 004915141238841 | F24: =VLOOKUP(D24,'Master Data'!A:F,4,FALSE) -> w | G24: =VLOOKUP(D24,'Master Data'!A:F,5,FALSE) -> Normal | H24: 190 | I24: - | J24: X | K24: X | L24: - | M24: X
A25: =VLOOKUP(D25,'Master Data'!A:F,2,FALSE) -> Mathias | B25: =VLOOKUP(D25,'Master Data'!A:F,3,FALSE) -> Landsrath | C25: =VLOOKUP(D25,'Master Data'!A:F,6,FALSE) -> matila@gmx.de | D25: 0766413136 | F25: =VLOOKUP(D25,'Master Data'!A:F,4,FALSE) -> m | G25: =VLOOKUP(D25,'Master Data'!A:F,5,FALSE) -> Normal | I25: - | J25: X | K25: - | M25: X | N25: -
A26: =VLOOKUP(D26,'Master Data'!A:F,2,FALSE) -> Michelle | B26: =VLOOKUP(D26,'Master Data'!A:F,3,FALSE) -> Harder | C26: =VLOOKUP(D26,'Master Data'!A:F,6,FALSE) -> michelle.harder@sunrise.ch | D26: 0763031188 | F26: =VLOOKUP(D26,'Master Data'!A:F,4,FALSE) -> w | G26: =VLOOKUP(D26,'Master Data'!A:F,5,FALSE) -> Normal | H26: 135 | I26: X | J26: - | K26: X | L26: - | M26: X | P26: -
A27: =VLOOKUP(D27,'Master Data'!A:F,2,FALSE) -> Umut | B27: =VLOOKUP(D27,'Master Data'!A:F,3,FALSE) -> Paldir | C27: =VLOOKUP(D27,'Master Data'!A:F,6,FALSE) -> umut.paldir@gmail.com | D27: 0798569600 | F27: =VLOOKUP(D27,'Master Data'!A:F,4,FALSE) -> m | G27: =VLOOKUP(D27,'Master Data'!A:F,5,FALSE) -> Normal | H27: 190 | I27: X | J27: - | K27: - | M27: X | O27: - | P27: -
A28: =VLOOKUP(D28,'Master Data'!A:F,2,FALSE) -> Haimo | B28: =VLOOKUP(D28,'Master Data'!A:F,3,FALSE) -> Jöhri | C28: =VLOOKUP(D28,'Master Data'!A:F,6,FALSE) -> paps1408@gmail.com | D28: 0763662642 | E28: Salsaflow Pass | F28: =VLOOKUP(D28,'Master Data'!A:F,4,FALSE) -> m | G28: =VLOOKUP(D28,'Master Data'!A:F,5,FALSE) -> Normal | H28: 410 | I28: X | J28: X | K28: X | M28: X | P28: -
A29: =VLOOKUP(D29,'Master Data'!A:F,2,FALSE) -> Sara | B29: =VLOOKUP(D29,'Master Data'!A:F,3,FALSE) -> Bettonte | C29: =VLOOKUP(D29,'Master Data'!A:F,6,FALSE) -> mattiabert93@gmail.com | D29: 0762326073 | F29: =VLOOKUP(D29,'Master Data'!A:F,4,FALSE) -> w | G29: =VLOOKUP(D29,'Master Data'!A:F,5,FALSE) -> Paar | H29: 190 | I29: - | J29: - | K29: X | M29: X | N29: -
A30: =VLOOKUP(D30,'Master Data'!A:F,2,FALSE) -> #N/A | B30: =VLOOKUP(D30,'Master Data'!A:F,3,FALSE) -> #N/A | C30: =VLOOKUP(D30,'Master Data'!A:F,6,FALSE) -> #N/A | F30: =VLOOKUP(D30,'Master Data'!A:F,4,FALSE) -> #N/A | G30: =VLOOKUP(D30,'Master Data'!A:F,5,FALSE) -> #N/A
A31: =VLOOKUP(D31,'Master Data'!A:F,2,FALSE) -> #N/A | B31: =VLOOKUP(D31,'Master Data'!A:F,3,FALSE) -> #N/A | C31: =VLOOKUP(D31,'Master Data'!A:F,5,FALSE) -> #N/A | F31: =VLOOKUP(D31,'Master Data'!A:F,4,FALSE) -> #N/A | G31: =VLOOKUP(D31,'Master Data'!A:F,5,FALSE) -> #N/A
A32: =VLOOKUP(D32,'Master Data'!A:F,2,FALSE) -> #N/A | B32: =VLOOKUP(D32,'Master Data'!A:F,3,FALSE) -> #N/A | C32: =VLOOKUP(D32,'Master Data'!A:F,5,FALSE) -> #N/A | G32: Einnahmen | H32: =SUM(H7:H31) -> 5055

Sheet Mo_Salsa Intermediate Stufe 8
A1: Anmeldungen - Salsa Intermediate 8
A3: Datum: | B3: 05.01.2026 - 02.03.2026 | D3: Kurstag: | E3: Montag | G3: Lehrer: | H3: Claudia & Maarten
A4: Zeit: | B4: 18:30 - 19:30 | D4: Ort: | E4: Elisabethenanlage 7 | G4: Preis: | H4: CHF 190.- / CHF 160.-
A6: Vorname | B6: Name | C6: E-Mail | D6: Mobile | E6: Bemerkungen | F6: m/w | G6: Tarif | H6: Betrag | I6: Anwesenheit
A7: =VLOOKUP(D7,'Master Data'!A:F,2,FALSE) -> Carmen | B7: =VLOOKUP(D7,'Master Data'!A:F,3,FALSE) -> Magno | C7: =VLOOKUP(D7,'Master Data'!A:F,6,FALSE) -> carmen_magno4@hotmail.com | D7: 0764535573 | F7: =VLOOKUP(D7,'Master Data'!A:F,4,FALSE) -> w | G7: =VLOOKUP(D7,'Master Data'!A:F,5,FALSE) -> Paar | H7: 160 | I7: X | J7: X | K7: - | M7: X | N7: - | O7: - | P7: -
A8: =VLOOKUP(D8,'Master Data'!A:F,2,FALSE) -> Lukas | B8: =VLOOKUP(D8,'Master Data'!A:F,3,FALSE) -> Kofmehl | C8: =VLOOKUP(D8,'Master Data'!A:F,6,FALSE) -> lkofmehl.lk@gmail.ch | D8: 0774063151 | F8: =VLOOKUP(D8,'Master Data'!A:F,4,FALSE) -> m | G8: =VLOOKUP(D8,'Master Data'!A:F,5,FALSE) -> Paar | H8: 160 | I8: X | J8: X | K8: - | M8: X | N8: - | O8: - | P8: -
A9: =VLOOKUP(D9,'Master Data'!A:F,2,FALSE) -> Eliane | B9: =VLOOKUP(D9,'Master Data'!A:F,3,FALSE) -> Schneeberger | C9: =VLOOKUP(D9,'Master Data'!A:F,6,FALSE) -> eliane.schneeberger@gmail.com | D9: 0795572430 | F9: =VLOOKUP(D9,'Master Data'!A:F,4,FALSE) -> w | G9: =VLOOKUP(D9,'Master Data'!A:F,5,FALSE) -> Normal | H9: 285 | I9: X | J9: X | K9: X | M9: X | N9: - | O9: -
A10: =VLOOKUP(D10,'Master Data'!A:F,2,FALSE) -> Alexandra | B10: =VLOOKUP(D10,'Master Data'!A:F,3,FALSE) -> Meyer | C10: =VLOOKUP(D10,'Master Data'!A:F,6,FALSE) -> lexxx.lexxx@gmail.com | D10: 0796580395 | E10: 2. Kurse | F10: =VLOOKUP(D10,'Master Data'!A:F,4,FALSE) -> w | G10: =VLOOKUP(D10,'Master Data'!A:F,5,FALSE) -> Normal | H10: 285 | I10: X | J10: X | K10: - | L10: - | M10: X | O10: -
A11: =VLOOKUP(D11,'Master Data'!A:F,2,FALSE) -> Katrin | B11: =VLOOKUP(D11,'Master Data'!A:F,3,FALSE) -> Schläpfer | C11: =VLOOKUP(D11,'Master Data'!A:F,6,FALSE) -> katrin.schlaepfer@edubs.ch | D11: 0792626602 | F11: =VLOOKUP(D11,'Master Data'!A:F,4,FALSE) -> w | G11: =VLOOKUP(D11,'Master Data'!A:F,5,FALSE) -> Normal | H11: 190 | I11: X | J11: X | K11: X | M11: X
A12: =VLOOKUP(D12,'Master Data'!A:F,2,FALSE) -> Elisa | B12: =VLOOKUP(D12,'Master Data'!A:F,3,FALSE) -> Benitez | C12: =VLOOKUP(D12,'Master Data'!A:F,6,FALSE) -> ebenitezgarcia@gmail.com | D12: 0782042740 | F12: =VLOOKUP(D12,'Master Data'!A:F,4,FALSE) -> w | G12: =VLOOKUP(D12,'Master Data'!A:F,5,FALSE) -> Normal | H12: 190 | I12: X | J12: X | K12: - | M12: X
A13: =VLOOKUP(D13,'Master Data'!A:F,2,FALSE) -> Fabio | B13: =VLOOKUP(D13,'Master Data'!A:F,3,FALSE) -> Vaschetto | C13: =VLOOKUP(D13,'Master Data'!A:F,6,FALSE) -> fabio.vaschetto@gmail.com | D13: 0796904915 | F13: =VLOOKUP(D13,'Master Data'!A:F,4,FALSE) -> m | G13: =VLOOKUP(D13,'Master Data'!A:F,5,FALSE) -> Normal | H13: 190 | I13: X | J13: X | K13: X | M13: -
A14: =VLOOKUP(D14,'Master Data'!A:F,2,FALSE) -> Kristijan | B14: =VLOOKUP(D14,'Master Data'!A:F,3,FALSE) -> Markovic | C14: =VLOOKUP(D14,'Master Data'!A:F,6,FALSE) -> kristijan1.markovic@gmail.com | D14: 0765608884 | F14: =VLOOKUP(D14,'Master Data'!A:F,4,FALSE) -> m | G14: =VLOOKUP(D14,'Master Data'!A:F,5,FALSE) -> Paar | H14: 190 | I14: X | J14: - | K14: - | L14: - | M14: X
A15: =VLOOKUP(D15,'Master Data'!A:F,2,FALSE) -> Lucyann | B15: =VLOOKUP(D15,'Master Data'!A:F,3,FALSE) -> Ceballos | C15: =VLOOKUP(D15,'Master Data'!A:F,6,FALSE) -> ceballos.lucyann@gmail.com | D15: 0017875053395 | E15: 2 halbe Kurse | F15: =VLOOKUP(D15,'Master Data'!A:F,4,FALSE) -> w | G15: =VLOOKUP(D15,'Master Data'!A:F,5,FALSE) -> Normal | H15: 240 | I15: - | J15: X | K15: X | M15: X
A16: =VLOOKUP(D16,'Master Data'!A:F,2,FALSE) -> Lana | B16: =VLOOKUP(D16,'Master Data'!A:F,3,FALSE) -> Vinigradova | C16: =VLOOKUP(D16,'Master Data'!A:F,6,FALSE) -> lanavin@gmail.com | D16: 0798866124 | E16: 2 halbe Kurse | F16: =VLOOKUP(D16,'Master Data'!A:F,4,FALSE) -> w | G16: =VLOOKUP(D16,'Master Data'!A:F,5,FALSE) -> Normal | H16: 190 | I16: X | J16: X | K16: X | M16: - | N16: - | O16: - | P16: -
A17: =VLOOKUP(D17,'Master Data'!A:F,2,FALSE) -> Sara | B17: =VLOOKUP(D17,'Master Data'!A:F,3,FALSE) -> Branca | C17: =VLOOKUP(D17,'Master Data'!A:F,6,FALSE) -> sara.branca@hotmail.com | D17: 0763739954 | F17: =VLOOKUP(D17,'Master Data'!A:F,4,FALSE) -> w | G17: =VLOOKUP(D17,'Master Data'!A:F,5,FALSE) -> Normal | H17: 160 | I17: X | J17: X | K17: X | M17: -
A18: =VLOOKUP(D18,'Master Data'!A:F,2,FALSE) -> Melina | B18: =VLOOKUP(D18,'Master Data'!A:F,3,FALSE) -> Götschi | C18: =VLOOKUP(D18,'Master Data'!A:F,6,FALSE) -> melinagoetschi@outlook.com | D18: 0795371219 | E18: 2. Kurse | F18: =VLOOKUP(D18,'Master Data'!A:F,4,FALSE) -> w | G18: =VLOOKUP(D18,'Master Data'!A:F,5,FALSE) -> Normal | I18: - | J18: X | K18: X | M18: X | N18: -
A19: =VLOOKUP(D19,'Master Data'!A:F,2,FALSE) -> Jacov | B19: =VLOOKUP(D19,'Master Data'!A:F,3,FALSE) -> Bludnikov | C19: =VLOOKUP(D19,'Master Data'!A:F,6,FALSE) -> 04jakov.bludnikov@gmail.com | D19: 0762630712 | F19: =VLOOKUP(D19,'Master Data'!A:F,4,FALSE) -> m | G19: =VLOOKUP(D19,'Master Data'!A:F,5,FALSE) -> Paar | H19: 160 | I19: X | J19: X | K19: X | M19: X
A20: =VLOOKUP(D20,'Master Data'!A:F,2,FALSE) -> Bianca | B20: =VLOOKUP(D20,'Master Data'!A:F,3,FALSE) -> Eichler | C20: =VLOOKUP(D20,'Master Data'!A:F,6,FALSE) -> bianca_eich.woelpp@hotmail.de | D20: 004915208262666 | F20: =VLOOKUP(D20,'Master Data'!A:F,4,FALSE) -> w | G20: =VLOOKUP(D20,'Master Data'!A:F,5,FALSE) -> Normal | H20: 190 | I20: X | J20: X | K20: - | M20: X
A21: =VLOOKUP(D21,'Master Data'!A:F,2,FALSE) -> Sabrina | B21: =VLOOKUP(D21,'Master Data'!A:F,3,FALSE) -> Grube | C21: =VLOOKUP(D21,'Master Data'!A:F,6,FALSE) -> Sabrina.Grube@gmx.net | D21: 00491795531616 | E21: Fehlt 1. Tag | F21: =VLOOKUP(D21,'Master Data'!A:F,4,FALSE) -> w | G21: =VLOOKUP(D21,'Master Data'!A:F,5,FALSE) -> Normal | H21: 190 | I21: - | J21: X | K21: X | M21: -
A22: =VLOOKUP(D22,'Master Data'!A:F,2,FALSE) -> Björn | B22: =VLOOKUP(D22,'Master Data'!A:F,3,FALSE) -> Friebe | C22: =VLOOKUP(D22,'Master Data'!A:F,6,FALSE) -> 0 | D22: 0762141635 | F22: =VLOOKUP(D22,'Master Data'!A:F,4,FALSE) -> m | G22: =VLOOKUP(D22,'Master Data'!A:F,5,FALSE) -> Paar | H22: 410 | I22: X | J22: X | K22: X | M22: x
A23: =VLOOKUP(D23,'Master Data'!A:F,2,FALSE) -> Lea | B23: =VLOOKUP(D23,'Master Data'!A:F,3,FALSE) -> Weibel | C23: =VLOOKUP(D23,'Master Data'!A:F,6,FALSE) -> lw23@bluewin.ch | D23: 0798729078 | F23: =VLOOKUP(D23,'Master Data'!A:F,4,FALSE) -> w | G23: =VLOOKUP(D23,'Master Data'!A:F,5,FALSE) -> Normal | H23: 190 | I23: X | J23: X | K23: X | M23: X | O23: -
A24: =VLOOKUP(D24,'Master Data'!A:F,2,FALSE) -> Marco Alessandro | B24: =VLOOKUP(D24,'Master Data'!A:F,3,FALSE) -> Pedrazzoli | C24: =VLOOKUP(D24,'Master Data'!A:F,6,FALSE) -> pedrazzolimarco07@gmail.com | D24: 0795764947 | E24: 2. Kurse | F24: =VLOOKUP(D24,'Master Data'!A:F,4,FALSE) -> m | G24: =VLOOKUP(D24,'Master Data'!A:F,5,FALSE) -> Normal | H24: 150 | I24: X | J24: X | K24: - | M24: X
A25: =VLOOKUP(D25,'Master Data'!A:F,2,FALSE) -> Magdalena | B25: =VLOOKUP(D25,'Master Data'!A:F,3,FALSE) -> Siedlok | C25: =VLOOKUP(D25,'Master Data'!A:F,6,FALSE) -> magdalena.siedlok@gmail.com | D25: 0767964603 | E25: Vom Freitag nachholen | F25: =VLOOKUP(D25,'Master Data'!A:F,4,FALSE) -> w | G25: =VLOOKUP(D25,'Master Data'!A:F,5,FALSE) -> Normal | H25: 145 | I25: x | J25: x | K25: - | L25: - | M25: - | N25: - | O25: - | P25: -
A26: =VLOOKUP(D26,'Master Data'!A:F,2,FALSE) -> #N/A | B26: =VLOOKUP(D26,'Master Data'!A:F,3,FALSE) -> #N/A | C26: =VLOOKUP(D26,'Master Data'!A:F,6,FALSE) -> #N/A | F26: =VLOOKUP(D26,'Master Data'!A:F,4,FALSE) -> #N/A | G26: =VLOOKUP(D26,'Master Data'!A:F,5,FALSE) -> #N/A
A27: =VLOOKUP(D27,'Master Data'!A:F,2,FALSE) -> #N/A | B27: =VLOOKUP(D27,'Master Data'!A:F,3,FALSE) -> #N/A | C27: =VLOOKUP(D27,'Master Data'!A:F,6,FALSE) -> #N/A | F27: =VLOOKUP(D27,'Master Data'!A:F,4,FALSE) -> #N/A | G27: =VLOOKUP(D27,'Master Data'!A:F,5,FALSE) -> #N/A
A28: =VLOOKUP(D28,'Master Data'!A:F,2,FALSE) -> #N/A | B28: =VLOOKUP(D28,'Master Data'!A:F,3,FALSE) -> #N/A | C28: =VLOOKUP(D28,'Master Data'!A:F,6,FALSE) -> #N/A | F28: =VLOOKUP(D28,'Master Data'!A:F,4,FALSE) -> #N/A | G28: =VLOOKUP(D28,'Master Data'!A:F,5,FALSE) -> #N/A
A29: =VLOOKUP(D29,'Master Data'!A:F,2,FALSE) -> #N/A | B29: =VLOOKUP(D29,'Master Data'!A:F,3,FALSE) -> #N/A | C29: =VLOOKUP(D29,'Master Data'!A:F,6,FALSE) -> #N/A | F29: =VLOOKUP(D29,'Master Data'!A:F,4,FALSE) -> #N/A | G29: =VLOOKUP(D29,'Master Data'!A:F,5,FALSE) -> #N/A
A30: =VLOOKUP(D30,'Master Data'!A:F,2,FALSE) -> #N/A | B30: =VLOOKUP(D30,'Master Data'!A:F,3,FALSE) -> #N/A | C30: =VLOOKUP(D30,'Master Data'!A:F,6,FALSE) -> #N/A | F30: =VLOOKUP(D30,'Master Data'!A:F,4,FALSE) -> #N/A | G30: =VLOOKUP(D30,'Master Data'!A:F,5,FALSE) -> #N/A
A31: =VLOOKUP(D31,'Master Data'!A:F,2,FALSE) -> #N/A | B31: =VLOOKUP(D31,'Master Data'!A:F,3,FALSE) -> #N/A | C31: =VLOOKUP(D31,'Master Data'!A:F,6,FALSE) -> #N/A | F31: =VLOOKUP(D31,'Master Data'!A:F,4,FALSE) -> #N/A | G31: =VLOOKUP(D31,'Master Data'!A:F,5,FALSE) -> #N/A
A32: =VLOOKUP(D32,'Master Data'!A:F,2,FALSE) -> #N/A | B32: =VLOOKUP(D32,'Master Data'!A:F,3,FALSE) -> #N/A | C32: =VLOOKUP(D32,'Master Data'!A:F,5,FALSE) -> #N/A | G32: Einnahmen | H32: =SUM(H7:H31) -> 3675

Sheet Mo_Salsa Beginner Stufe 3
A1: Anmeldungen - Salsa Beginner Stufe 3
A3: Datum: | B3: 05.01.2026 - 02.03.2026 | D3: Kurstag: | E3: Montag | G3: Lehrer: | H3: John
A4: Zeit: | B4: 18:30 - 19:30 | D4: Ort: | E4: Elisabethenanlage 7 | G4: Preis: | H4: CHF 190.- / CHF 160.-
A6: Vorname | B6: Name | C6: E-Mail | D6: Mobile | E6: Bemerkungen | F6: m/w | G6: Tarif | H6: Betrag | I6: Anwesenheit
A7: =VLOOKUP(D7,'Master Data'!A:F,2,FALSE) -> Simone | B7: =VLOOKUP(D7,'Master Data'!A:F,3,FALSE) -> Frey | C7: =VLOOKUP(D7,'Master Data'!A:F,6,FALSE) -> simone-frey@hotmail.de | D7: 0798881391 | F7: =VLOOKUP(D7,'Master Data'!A:F,4,FALSE) -> w | G7: =VLOOKUP(D7,'Master Data'!A:F,5,FALSE) -> Normal | H7: 190 | I7: X | J7: - | L7: - | M7: X | P7: -
A8: =VLOOKUP(D8,'Master Data'!A:F,2,FALSE) -> Nadja | B8: =VLOOKUP(D8,'Master Data'!A:F,3,FALSE) -> Agreda | C8: =VLOOKUP(D8,'Master Data'!A:F,6,FALSE) -> nadja_agreda@hotmail.com | D8: 0787271733 | E8: Helvetia | F8: =VLOOKUP(D8,'Master Data'!A:F,4,FALSE) -> w | G8: =VLOOKUP(D8,'Master Data'!A:F,5,FALSE) -> Paar | H8: 160 | J8: X | M8: X
A9: =VLOOKUP(D9,'Master Data'!A:F,2,FALSE) -> Christian | B9: =VLOOKUP(D9,'Master Data'!A:F,3,FALSE) -> Perren | C9: =VLOOKUP(D9,'Master Data'!A:F,6,FALSE) -> 0 | D9: 0787271733-1 | E9: Helvetia | F9: =VLOOKUP(D9,'Master Data'!A:F,4,FALSE) -> m | G9: =VLOOKUP(D9,'Master Data'!A:F,5,FALSE) -> Paar | H9: 160 | J9: X | M9: X
A10: =VLOOKUP(D10,'Master Data'!A:F,2,FALSE) -> Yasmin | B10: =VLOOKUP(D10,'Master Data'!A:F,3,FALSE) -> Blum | C10: =VLOOKUP(D10,'Master Data'!A:F,6,FALSE) -> blumyas@gmail.com | D10: 0764186668 | F10: =VLOOKUP(D10,'Master Data'!A:F,4,FALSE) -> w | G10: =VLOOKUP(D10,'Master Data'!A:F,5,FALSE) -> Normal | H10: 170 | J10: X | M10: -
A11: =VLOOKUP(D11,'Master Data'!A:F,2,FALSE) -> Marija | B11: =VLOOKUP(D11,'Master Data'!A:F,3,FALSE) -> Milenkovic | C11: =VLOOKUP(D11,'Master Data'!A:F,6,FALSE) -> marijamilenkovic7@hotmail.com | D11: 0788325297 | E11: Salsaflow Pass | F11: =VLOOKUP(D11,'Master Data'!A:F,4,FALSE) -> w | G11: =VLOOKUP(D11,'Master Data'!A:F,5,FALSE) -> Normal | H11: 410 | I11: X | J11: X | M11: X | O11: -
A12: =VLOOKUP(D12,'Master Data'!A:F,2,FALSE) -> Esther | B12: =VLOOKUP(D12,'Master Data'!A:F,3,FALSE) -> Matt | C12: =VLOOKUP(D12,'Master Data'!A:F,6,FALSE) -> ematt@gmx.ch | D12: 0795873438 | F12: m | G12: =VLOOKUP(D12,'Master Data'!A:F,5,FALSE) -> Normal | I12: X | J12: - | M12: X
A13: =VLOOKUP(D13,'Master Data'!A:F,2,FALSE) -> Simão Pedro | B13: =VLOOKUP(D13,'Master Data'!A:F,3,FALSE) -> Oliveira | C13: =VLOOKUP(D13,'Master Data'!A:F,6,FALSE) -> spedro.oliveira@gmail.com | D13: 0033681301330 | F13: =VLOOKUP(D13,'Master Data'!A:F,4,FALSE) -> m | G13: =VLOOKUP(D13,'Master Data'!A:F,5,FALSE) -> Normal | I13: X | J13: X | M13: X
A14: =VLOOKUP(D14,'Master Data'!A:F,2,FALSE) -> Julie | B14: =VLOOKUP(D14,'Master Data'!A:F,3,FALSE) -> Pfenninger | C14: =VLOOKUP(D14,'Master Data'!A:F,6,FALSE) -> j.pfenninger@hotmail.com | D14: 0786277824 | F14: =VLOOKUP(D14,'Master Data'!A:F,4,FALSE) -> w | G14: =VLOOKUP(D14,'Master Data'!A:F,5,FALSE) -> Normal | H14: 285 | I14: X | J14: X | M14: X
A15: =VLOOKUP(D15,'Master Data'!A:F,2,FALSE) -> Simone | B15: =VLOOKUP(D15,'Master Data'!A:F,3,FALSE) -> Schmutz | C15: =VLOOKUP(D15,'Master Data'!A:F,6,FALSE) -> simi_s_88@hotmail.com | D15: 0797374604 | E15: Zahlen später | F15: =VLOOKUP(D15,'Master Data'!A:F,4,FALSE) -> w | G15: =VLOOKUP(D15,'Master Data'!A:F,5,FALSE) -> Normal | H15: 160 | I15: X | J15: X | M15: X
A16: =VLOOKUP(D16,'Master Data'!A:F,2,FALSE) -> Pascal | B16: =VLOOKUP(D16,'Master Data'!A:F,3,FALSE) -> Howald | C16: =VLOOKUP(D16,'Master Data'!A:F,6,FALSE) -> 0 | D16: 0764484023 | E16: Zahlen später | F16: =VLOOKUP(D16,'Master Data'!A:F,4,FALSE) -> m | G16: =VLOOKUP(D16,'Master Data'!A:F,5,FALSE) -> Paar | H16: 160 | I16: X | J16: X | M16: X
A17: =VLOOKUP(D17,'Master Data'!A:F,2,FALSE) -> Inigo | B17: =VLOOKUP(D17,'Master Data'!A:F,3,FALSE) -> de la Maza | C17: =VLOOKUP(D17,'Master Data'!A:F,6,FALSE) -> i.delamaza.prieto@gmail.com | D17: 0795541328 | F17: =VLOOKUP(D17,'Master Data'!A:F,4,FALSE) -> m | G17: =VLOOKUP(D17,'Master Data'!A:F,5,FALSE) -> Normal | H17: 285 | I17: X | J17: X | M17: X
A18: =VLOOKUP(D18,'Master Data'!A:F,2,FALSE) -> Simon | B18: =VLOOKUP(D18,'Master Data'!A:F,3,FALSE) -> Burri | C18: =VLOOKUP(D18,'Master Data'!A:F,6,FALSE) -> simon.henry.burri@gmail.com | D18: 0774461136 | F18: =VLOOKUP(D18,'Master Data'!A:F,4,FALSE) -> m | G18: =VLOOKUP(D18,'Master Data'!A:F,5,FALSE) -> Normal | I18: - | J18: X | L18: - | M18: X | P18: -
A19: =VLOOKUP(D19,'Master Data'!A:F,2,FALSE) -> Christoph | B19: =VLOOKUP(D19,'Master Data'!A:F,3,FALSE) -> Isele | C19: =VLOOKUP(D19,'Master Data'!A:F,6,FALSE) -> christoph.isele@hotmail.de | D19: 0767056863 | F19: =VLOOKUP(D19,'Master Data'!A:F,4,FALSE) -> m | G19: =VLOOKUP(D19,'Master Data'!A:F,5,FALSE) -> Normal | H19: 190 | I19: X | J19: X | M19: X
A20: =VLOOKUP(D20,'Master Data'!A:F,2,FALSE) -> Ivan | B20: =VLOOKUP(D20,'Master Data'!A:F,3,FALSE) -> Zuparic | C20: =VLOOKUP(D20,'Master Data'!A:F,6,FALSE) -> ivan.zuparic@gmx.ch | D20: 0793691732 | E20: 2. Kurse | F20: =VLOOKUP(D20,'Master Data'!A:F,4,FALSE) -> m | G20: =VLOOKUP(D20,'Master Data'!A:F,5,FALSE) -> Normal | I20: - | J20: X | M20: - | N20: - | P20: -
A21: =VLOOKUP(D21,'Master Data'!A:F,2,FALSE) -> Antonio | B21: =VLOOKUP(D21,'Master Data'!A:F,3,FALSE) -> Piazza | C21: =VLOOKUP(D21,'Master Data'!A:F,6,FALSE) -> anpiazza@bluewin.ch | D21: 0793750430 | E21: 0.2 | F21: =VLOOKUP(D21,'Master Data'!A:F,4,FALSE) -> m | G21: =VLOOKUP(D21,'Master Data'!A:F,5,FALSE) -> Paar | H21: 256 | I21: X | J21: X | M21: X
A22: =VLOOKUP(D22,'Master Data'!A:F,2,FALSE) -> Angela | B22: =VLOOKUP(D22,'Master Data'!A:F,3,FALSE) -> Piazza | C22: =VLOOKUP(D22,'Master Data'!A:F,6,FALSE) -> 0 | D22: 0793750430-1 | E22: 0.2 | F22: =VLOOKUP(D22,'Master Data'!A:F,4,FALSE) -> w | G22: =VLOOKUP(D22,'Master Data'!A:F,5,FALSE) -> Paar | I22: X | J22: X | M22: X
A23: =VLOOKUP(D23,'Master Data'!A:F,2,FALSE) -> Alexander | B23: =VLOOKUP(D23,'Master Data'!A:F,3,FALSE) -> Egger | C23: =VLOOKUP(D23,'Master Data'!A:F,6,FALSE) -> 0 | D23: 0774087049 | F23: =VLOOKUP(D23,'Master Data'!A:F,4,FALSE) -> m | G23: =VLOOKUP(D23,'Master Data'!A:F,5,FALSE) -> Paar | H23: 160 | I23: X | J23: X | M23: X
A24: =VLOOKUP(D24,'Master Data'!A:F,2,FALSE) -> Daniela | B24: =VLOOKUP(D24,'Master Data'!A:F,3,FALSE) -> Egger | C24: =VLOOKUP(D24,'Master Data'!A:F,6,FALSE) -> daniela.schaffner@hotmail.com | D24: 0774087049-1 | F24: =VLOOKUP(D24,'Master Data'!A:F,4,FALSE) -> w | G24: =VLOOKUP(D24,'Master Data'!A:F,5,FALSE) -> Paar | H24: 160 | I24: X | J24: X | M24: X
A25: Alexandra soare | B25: =VLOOKUP(D25,'Master Data'!A:F,3,FALSE) -> Soare | C25: =VLOOKUP(D25,'Master Data'!A:F,6,FALSE) -> soare.alexandra95@yahoo.com | D25: 0795606944 | F25: =VLOOKUP(D25,'Master Data'!A:F,4,FALSE) -> w | G25: =VLOOKUP(D25,'Master Data'!A:F,5,FALSE) -> Normal | H25: 190 | I25: X | J25: X | M25: X
A26: =VLOOKUP(D26,'Master Data'!A:F,2,FALSE) -> Ivan | B26: =VLOOKUP(D26,'Master Data'!A:F,3,FALSE) -> Glushenkov | C26: =VLOOKUP(D26,'Master Data'!A:F,6,FALSE) -> ivan.glushenkov.data@gmail.com | D26: 0762636496 | E26: Salsaflow Pass | F26: =VLOOKUP(D26,'Master Data'!A:F,4,FALSE) -> m | G26: =VLOOKUP(D26,'Master Data'!A:F,5,FALSE) -> Normal | J26: X | M26: X
A27: =VLOOKUP(D27,'Master Data'!A:F,2,FALSE) -> Ben | B27: =VLOOKUP(D27,'Master Data'!A:F,3,FALSE) -> Böke | C27: =VLOOKUP(D27,'Master Data'!A:F,6,FALSE) -> ben25boeke@gmail.com | D27: 00491602122888 | E27: Salsaflow Pass | F27: =VLOOKUP(D27,'Master Data'!A:F,4,FALSE) -> m | G27: =VLOOKUP(D27,'Master Data'!A:F,5,FALSE) -> Normal | J27: X | M27: X
A28: =VLOOKUP(D28,'Master Data'!A:F,2,FALSE) -> Meral | B28: =VLOOKUP(D28,'Master Data'!A:F,3,FALSE) -> Bozkiraç | C28: =VLOOKUP(D28,'Master Data'!A:F,6,FALSE) -> meral.bozkirac@gmail.com | D28: 0783342600 | E28: 2. Kurse | F28: =VLOOKUP(D28,'Master Data'!A:F,4,FALSE) -> w | G28: =VLOOKUP(D28,'Master Data'!A:F,5,FALSE) -> Normal | H28: 190 | M28: X
A29: =VLOOKUP(D29,'Master Data'!A:F,2,FALSE) -> David | B29: =VLOOKUP(D29,'Master Data'!A:F,3,FALSE) -> Schwegler | C29: =VLOOKUP(D29,'Master Data'!A:F,6,FALSE) -> davidschweg@gmail.com | D29: 0774907360 | F29: =VLOOKUP(D29,'Master Data'!A:F,4,FALSE) -> m | G29: =VLOOKUP(D29,'Master Data'!A:F,5,FALSE) -> Normal | H29: 190 | M29: X
A30: =VLOOKUP(D30,'Master Data'!A:F,2,FALSE) -> #N/A | B30: =VLOOKUP(D30,'Master Data'!A:F,3,FALSE) -> #N/A | C30: =VLOOKUP(D30,'Master Data'!A:F,6,FALSE) -> #N/A | F30: =VLOOKUP(D30,'Master Data'!A:F,4,FALSE) -> #N/A | G30: =VLOOKUP(D30,'Master Data'!A:F,5,FALSE) -> #N/A
A31: =VLOOKUP(D31,'Master Data'!A:F,2,FALSE) -> #N/A | B31: =VLOOKUP(D31,'Master Data'!A:F,3,FALSE) -> #N/A | C31: =VLOOKUP(D31,'Master Data'!A:F,6,FALSE) -> #N/A | F31: =VLOOKUP(D31,'Master Data'!A:F,4,FALSE) -> #N/A | G31: =VLOOKUP(D31,'Master Data'!A:F,5,FALSE) -> #N/A | M31: .
A32: =VLOOKUP(D32,'Master Data'!A:F,2,FALSE) -> #N/A | B32: =VLOOKUP(D32,'Master Data'!A:F,3,FALSE) -> #N/A | C32: =VLOOKUP(D32,'Master Data'!A:F,5,FALSE) -> #N/A | F32: =VLOOKUP(D32,'Master Data'!A:F,4,FALSE) -> #N/A | G32: =VLOOKUP(D32,'Master Data'!A:F,5,FALSE) -> #N/A | H32: =SUM(H7:H31) -> 3316

Sheet Mo_Salsa Advanced Stufe 17
A1: Anmeldungen - Salsa Advanced Stufe 17
A3: Datum: | B3: 05.01.2026 - 02.03.2026 | D3: Kurstag: | E3: Montag | G3: Lehrer: | H3: Viviana & Sebastian
A4: Zeit: | B4: 19:30 - 20:30 | D4: Ort: | E4: Elisabethenanlage 7 | G4: Preis: | H4: CHF 190.- / CHF 160.-
A6: Vorname | B6: Name | C6: E-Mail | D6: Mobile | E6: Bemerkungen | F6: m/w | G6: Tarif | H6: Betrag | I6: Anwesenheit
A7: =VLOOKUP(D7,'Master Data'!A:F,2,FALSE) -> Manuel | B7: =VLOOKUP(D7,'Master Data'!A:F,3,FALSE) -> Field | C7: =VLOOKUP(D7,'Master Data'!A:F,6,FALSE) -> manu@cantab.net | D7: 0795392476 | F7: =VLOOKUP(D7,'Master Data'!A:F,4,FALSE) -> m | G7: =VLOOKUP(D7,'Master Data'!A:F,5,FALSE) -> Normal | H7: 190 | I7: X | J7: X | K7: X | M7: X | O7: -
A8: =VLOOKUP(D8,'Master Data'!A:F,2,FALSE) -> Gensan | B8: =VLOOKUP(D8,'Master Data'!A:F,3,FALSE) -> Thavarajah | C8: =VLOOKUP(D8,'Master Data'!A:F,6,FALSE) -> gensan.t@hotmail.ch | D8: 0793676399 | F8: =VLOOKUP(D8,'Master Data'!A:F,4,FALSE) -> m | G8: =VLOOKUP(D8,'Master Data'!A:F,5,FALSE) -> Normal | H8: 285 | I8: X | J8: X | K8: X | M8: X
A9: =VLOOKUP(D9,'Master Data'!A:F,2,FALSE) -> Theresa | B9: =VLOOKUP(D9,'Master Data'!A:F,3,FALSE) -> Reiker | C9: =VLOOKUP(D9,'Master Data'!A:F,6,FALSE) -> gvilanovaa@gmail.com | D9: 0799208215 | F9: =VLOOKUP(D9,'Master Data'!A:F,4,FALSE) -> w | G9: =VLOOKUP(D9,'Master Data'!A:F,5,FALSE) -> Paar | H9: 190 | I9: X | J9: X | K9: - | M9: X
A10: =VLOOKUP(D10,'Master Data'!A:F,2,FALSE) -> Mathias | B10: =VLOOKUP(D10,'Master Data'!A:F,3,FALSE) -> Landsrath | C10: =VLOOKUP(D10,'Master Data'!A:F,6,FALSE) -> matila@gmx.de | D10: 0766413136 | F10: =VLOOKUP(D10,'Master Data'!A:F,4,FALSE) -> m | G10: =VLOOKUP(D10,'Master Data'!A:F,5,FALSE) -> Normal | I10: - | J10: X | K10: - | M10: X | N10: -
A11: =VLOOKUP(D11,'Master Data'!A:F,2,FALSE) -> Sarah | B11: =VLOOKUP(D11,'Master Data'!A:F,3,FALSE) -> Imhof | C11: =VLOOKUP(D11,'Master Data'!A:F,6,FALSE) -> sarah.imhof60@gmail.com | D11: 0787478553 | F11: =VLOOKUP(D11,'Master Data'!A:F,4,FALSE) -> w | G11: =VLOOKUP(D11,'Master Data'!A:F,5,FALSE) -> Paar | I11: X | J11: X | K11: X | M11: X | N11: -
A12: =VLOOKUP(D12,'Master Data'!A:F,2,FALSE) -> Moritz | B12: =VLOOKUP(D12,'Master Data'!A:F,3,FALSE) -> Bachmann | C12: =VLOOKUP(D12,'Master Data'!A:F,6,FALSE) -> moritz.bachmann@roche.com | D12: 0033642737725 | F12: =VLOOKUP(D12,'Master Data'!A:F,4,FALSE) -> m | G12: =VLOOKUP(D12,'Master Data'!A:F,5,FALSE) -> Normal | H12: 410 | I12: X | J12: X | K12: - | M12: X | O12: -
A13: =VLOOKUP(D13,'Master Data'!A:F,2,FALSE) -> Merlin | B13: =VLOOKUP(D13,'Master Data'!A:F,3,FALSE) -> Zeugin | C13: =VLOOKUP(D13,'Master Data'!A:F,6,FALSE) -> 0 | D13: 0794542820 | F13: =VLOOKUP(D13,'Master Data'!A:F,4,FALSE) -> m | G13: =VLOOKUP(D13,'Master Data'!A:F,5,FALSE) -> Normal | H13: 190 | I13: - | J13: X | K13: - | L13: - | M13: - | N13: - | O13: -
A14: =VLOOKUP(D14,'Master Data'!A:F,2,FALSE) -> Stephanie | B14: =VLOOKUP(D14,'Master Data'!A:F,3,FALSE) -> Csendes | C14: =VLOOKUP(D14,'Master Data'!A:F,6,FALSE) -> stephanie.csendes@gmail.com | D14: 0764177421 | F14: =VLOOKUP(D14,'Master Data'!A:F,4,FALSE) -> w | G14: =VLOOKUP(D14,'Master Data'!A:F,5,FALSE) -> Normal | I14: X | J14: X | K14: X | M14: X
A15: =VLOOKUP(D15,'Master Data'!A:F,2,FALSE) -> Myriam | B15: =VLOOKUP(D15,'Master Data'!A:F,3,FALSE) -> Aouadi | C15: =VLOOKUP(D15,'Master Data'!A:F,6,FALSE) -> aouadme@gmail.com | D15: 0795404172 | F15: =VLOOKUP(D15,'Master Data'!A:F,4,FALSE) -> w | G15: =VLOOKUP(D15,'Master Data'!A:F,5,FALSE) -> Normal | I15: - | J15: X | K15: X | M15: X
A16: =VLOOKUP(D16,'Master Data'!A:F,2,FALSE) -> #N/A | B16: =VLOOKUP(D16,'Master Data'!A:F,3,FALSE) -> #N/A | C16: =VLOOKUP(D16,'Master Data'!A:F,6,FALSE) -> #N/A | F16: =VLOOKUP(D16,'Master Data'!A:F,4,FALSE) -> #N/A | G16: =VLOOKUP(D16,'Master Data'!A:F,5,FALSE) -> #N/A
A17: =VLOOKUP(D17,'Master Data'!A:F,2,FALSE) -> #N/A | B17: =VLOOKUP(D17,'Master Data'!A:F,3,FALSE) -> #N/A | C17: =VLOOKUP(D17,'Master Data'!A:F,6,FALSE) -> #N/A | F17: =VLOOKUP(D17,'Master Data'!A:F,4,FALSE) -> #N/A | G17: =VLOOKUP(D17,'Master Data'!A:F,5,FALSE) -> #N/A
A18: =VLOOKUP(D18,'Master Data'!A:F,2,FALSE) -> #N/A | B18: =VLOOKUP(D18,'Master Data'!A:F,3,FALSE) -> #N/A | C18: =VLOOKUP(D18,'Master Data'!A:F,6,FALSE) -> #N/A | F18: =VLOOKUP(D18,'Master Data'!A:F,4,FALSE) -> #N/A | G18: =VLOOKUP(D18,'Master Data'!A:F,5,FALSE) -> #N/A
A19: =VLOOKUP(D19,'Master Data'!A:F,2,FALSE) -> #N/A | B19: =VLOOKUP(D19,'Master Data'!A:F,3,FALSE) -> #N/A | C19: =VLOOKUP(D19,'Master Data'!A:F,6,FALSE) -> #N/A | F19: =VLOOKUP(D19,'Master Data'!A:F,4,FALSE) -> #N/A | G19: =VLOOKUP(D19,'Master Data'!A:F,5,FALSE) -> #N/A
A20: =VLOOKUP(D20,'Master Data'!A:F,2,FALSE) -> #N/A | B20: =VLOOKUP(D20,'Master Data'!A:F,3,FALSE) -> #N/A | C20: =VLOOKUP(D20,'Master Data'!A:F,6,FALSE) -> #N/A | F20: =VLOOKUP(D20,'Master Data'!A:F,4,FALSE) -> #N/A | G20: =VLOOKUP(D20,'Master Data'!A:F,5,FALSE) -> #N/A
A21: =VLOOKUP(D21,'Master Data'!A:F,2,FALSE) -> #N/A | B21: =VLOOKUP(D21,'Master Data'!A:F,3,FALSE) -> #N/A | C21: =VLOOKUP(D21,'Master Data'!A:F,6,FALSE) -> #N/A | F21: =VLOOKUP(D21,'Master Data'!A:F,4,FALSE) -> #N/A | G21: =VLOOKUP(D21,'Master Data'!A:F,5,FALSE) -> #N/A
A22: =VLOOKUP(D22,'Master Data'!A:F,2,FALSE) -> #N/A | B22: =VLOOKUP(D22,'Master Data'!A:F,3,FALSE) -> #N/A | C22: =VLOOKUP(D22,'Master Data'!A:F,6,FALSE) -> #N/A | F22: =VLOOKUP(D22,'Master Data'!A:F,4,FALSE) -> #N/A | G22: =VLOOKUP(D22,'Master Data'!A:F,5,FALSE) -> #N/A
A23: =VLOOKUP(D23,'Master Data'!A:F,2,FALSE) -> #N/A | B23: =VLOOKUP(D23,'Master Data'!A:F,3,FALSE) -> #N/A | C23: =VLOOKUP(D23,'Master Data'!A:F,6,FALSE) -> #N/A | F23: =VLOOKUP(D23,'Master Data'!A:F,4,FALSE) -> #N/A | G23: =VLOOKUP(D23,'Master Data'!A:F,5,FALSE) -> #N/A
A24: =VLOOKUP(D24,'Master Data'!A:F,2,FALSE) -> #N/A | B24: =VLOOKUP(D24,'Master Data'!A:F,3,FALSE) -> #N/A | C24: =VLOOKUP(D24,'Master Data'!A:F,6,FALSE) -> #N/A | F24: =VLOOKUP(D24,'Master Data'!A:F,4,FALSE) -> #N/A | G24: =VLOOKUP(D24,'Master Data'!A:F,5,FALSE) -> #N/A
A25: =VLOOKUP(D25,'Master Data'!A:F,2,FALSE) -> #N/A | B25: =VLOOKUP(D25,'Master Data'!A:F,3,FALSE) -> #N/A | C25: =VLOOKUP(D25,'Master Data'!A:F,6,FALSE) -> #N/A | F25: =VLOOKUP(D25,'Master Data'!A:F,4,FALSE) -> #N/A | G25: =VLOOKUP(D25,'Master Data'!A:F,5,FALSE) -> #N/A
A26: =VLOOKUP(D26,'Master Data'!A:F,2,FALSE) -> #N/A | B26: =VLOOKUP(D26,'Master Data'!A:F,3,FALSE) -> #N/A | C26: =VLOOKUP(D26,'Master Data'!A:F,6,FALSE) -> #N/A | F26: =VLOOKUP(D26,'Master Data'!A:F,4,FALSE) -> #N/A | G26: =VLOOKUP(D26,'Master Data'!A:F,5,FALSE) -> #N/A
A27: =VLOOKUP(D27,'Master Data'!A:F,2,FALSE) -> #N/A | B27: =VLOOKUP(D27,'Master Data'!A:F,3,FALSE) -> #N/A | C27: =VLOOKUP(D27,'Master Data'!A:F,6,FALSE) -> #N/A | F27: =VLOOKUP(D27,'Master Data'!A:F,4,FALSE) -> #N/A | G27: =VLOOKUP(D27,'Master Data'!A:F,5,FALSE) -> #N/A
... A31: =VLOOKUP(D31,'Master Data'!A:F,2,FALSE) -> #N/A | B31: =VLOOKUP(D31,'Master Data'!A:F,3,FALSE) -> #N/A | C31: =VLOOKUP(D31,'Master Data'!A:F,6,FALSE) -> #N/A | F31: =VLOOKUP(D31,'Master Data'!A:F,4,FALSE) -> #N/A | G31: =VLOOKUP(D31,'Master Data'!A:F,5,FALSE) -> #N/A
A32: =VLOOKUP(D32,'Master Data'!A:F,2,FALSE) -> #N/A | B32: =VLOOKUP(D32,'Master Data'!A:F,3,FALSE) -> #N/A | C32: =VLOOKUP(D32,'Master Data'!A:F,5,FALSE) -> #N/A | G32: Einnahmen | H32: =SUM(H7:H31) -> 1265

Sheet Mo_Salsa Intermediate Flow
A1: Anmeldungen - Salsa Intermediate Flow
A3: Datum: | B3: 05.01.2026 - 02.03.2026 | D3: Kurstag: | E3: Montag | G3: Lehrer: | H3: Claudia & Maarten
A4: Zeit: | B4: 19:30 - 20:30 | D4: Ort: | E4: Elisabethenanlage 7 | G4: Preis: | H4: CHF 190.- / CHF 160.-
A6: Vorname | B6: Name | C6: E-Mail | D6: Mobile | E6: Bemerkungen | F6: m/w | G6: Tarif | H6: Betrag | I6: Anwesenheit
A7: =VLOOKUP(D7,'Master Data'!A:F,2,FALSE) -> Michelle | B7: =VLOOKUP(D7,'Master Data'!A:F,3,FALSE) -> Wülser | C7: =VLOOKUP(D7,'Master Data'!A:F,6,FALSE) -> michellew@gmx.ch | D7: 0774406365 | F7: =VLOOKUP(D7,'Master Data'!A:F,4,FALSE) -> w | G7: =VLOOKUP(D7,'Master Data'!A:F,5,FALSE) -> Normal | H7: 160 | J7: X | L7: x | M7: x | N7: -
A8: =VLOOKUP(D8,'Master Data'!A:F,2,FALSE) -> Nora | B8: =VLOOKUP(D8,'Master Data'!A:F,3,FALSE) -> Weber | C8: =VLOOKUP(D8,'Master Data'!A:F,6,FALSE) -> nora.weber@outlook.com | D8: 0798536344 | F8: =VLOOKUP(D8,'Master Data'!A:F,4,FALSE) -> w | G8: =VLOOKUP(D8,'Master Data'!A:F,5,FALSE) -> Normal | H8: 190 | I8: X | J8: X | L8: - | M8: x | P8: -
A9: =VLOOKUP(D9,'Master Data'!A:F,2,FALSE) -> Nikki | B9: =VLOOKUP(D9,'Master Data'!A:F,3,FALSE) -> Parsons | C9: =VLOOKUP(D9,'Master Data'!A:F,6,FALSE) -> nikk.a.parsons@gmail.com | D9: 0792229499 | F9: =VLOOKUP(D9,'Master Data'!A:F,4,FALSE) -> w | G9: =VLOOKUP(D9,'Master Data'!A:F,5,FALSE) -> Normal | H9: 90 | I9: X | J9: X | M9: - | N9: - | O9: - | P9: -
A10: =VLOOKUP(D10,'Master Data'!A:F,2,FALSE) -> Helena | B10: =VLOOKUP(D10,'Master Data'!A:F,3,FALSE) -> Comas | C10: =VLOOKUP(D10,'Master Data'!A:F,6,FALSE) -> helenaccreus@gmail.com | D10: 0767812471 | F10: =VLOOKUP(D10,'Master Data'!A:F,4,FALSE) -> w | G10: =VLOOKUP(D10,'Master Data'!A:F,5,FALSE) -> Normal | H10: 190 | I10: - | J10: - | M10: x | N10: - | P10: -
A11: =VLOOKUP(D11,'Master Data'!A:F,2,FALSE) -> Afaf | B11: =VLOOKUP(D11,'Master Data'!A:F,3,FALSE) -> Elkurdi | C11: =VLOOKUP(D11,'Master Data'!A:F,6,FALSE) -> elkurdi_afaf@hotmail.com | D11: 0766035326 | F11: =VLOOKUP(D11,'Master Data'!A:F,4,FALSE) -> w | G11: =VLOOKUP(D11,'Master Data'!A:F,5,FALSE) -> Normal | H11: 228 | I11: x | J11: x | K11: x | L11: x | M11: x | N11: x
A12: =VLOOKUP(D12,'Master Data'!A:F,2,FALSE) -> Daniel | B12: =VLOOKUP(D12,'Master Data'!A:F,3,FALSE) -> Hoffmann | C12: =VLOOKUP(D12,'Master Data'!A:F,6,FALSE) -> daniel.pascal.hoffmann@gmail.com | D12: 0765055780 | F12: =VLOOKUP(D12,'Master Data'!A:F,4,FALSE) -> m | G12: =VLOOKUP(D12,'Master Data'!A:F,5,FALSE) -> Normal | I12: X | J12: X | M12: x
A13: =VLOOKUP(D13,'Master Data'!A:F,2,FALSE) -> Selina | B13: =VLOOKUP(D13,'Master Data'!A:F,3,FALSE) -> Schenker | C13: =VLOOKUP(D13,'Master Data'!A:F,6,FALSE) -> selina.schenker@live.de | D13: 0793283745 | F13: =VLOOKUP(D13,'Master Data'!A:F,4,FALSE) -> w | G13: =VLOOKUP(D13,'Master Data'!A:F,5,FALSE) -> Normal | I13: X | J13: X | M13: x
A14: =VLOOKUP(D14,'Master Data'!A:F,2,FALSE) -> Luca | B14: =VLOOKUP(D14,'Master Data'!A:F,3,FALSE) -> Pertoldi | C14: =VLOOKUP(D14,'Master Data'!A:F,6,FALSE) -> pertoldi@gmx.net | D14: 0763887046 | F14: =VLOOKUP(D14,'Master Data'!A:F,4,FALSE) -> m | G14: =VLOOKUP(D14,'Master Data'!A:F,5,FALSE) -> Normal | H14: 190 | I14: - | J14: X | M14: -
A15: =VLOOKUP(D15,'Master Data'!A:F,2,FALSE) -> Tobias | B15: =VLOOKUP(D15,'Master Data'!A:F,3,FALSE) -> Thommen | C15: =VLOOKUP(D15,'Master Data'!A:F,6,FALSE) -> tobithommen@hotmail.com | D15: 0798115348 | F15: =VLOOKUP(D15,'Master Data'!A:F,4,FALSE) -> m | G15: =VLOOKUP(D15,'Master Data'!A:F,5,FALSE) -> Normal | I15: X | J15: - | K15: - | M15: x | N15: - | O15: -
A16: =VLOOKUP(D16,'Master Data'!A:F,2,FALSE) -> Esther | B16: =VLOOKUP(D16,'Master Data'!A:F,3,FALSE) -> Matt | C16: =VLOOKUP(D16,'Master Data'!A:F,6,FALSE) -> ematt@gmx.ch | D16: 0795873438 | F16: =VLOOKUP(D16,'Master Data'!A:F,4,FALSE) -> w | G16: =VLOOKUP(D16,'Master Data'!A:F,5,FALSE) -> Normal | H16: 285 | I16: X | J16: X | M16: -
A17: =VLOOKUP(D17,'Master Data'!A:F,2,FALSE) -> Lukas | B17: =VLOOKUP(D17,'Master Data'!A:F,3,FALSE) -> Erni | C17: =VLOOKUP(D17,'Master Data'!A:F,6,FALSE) -> ernilweber@icloud.com | D17: 0792141383 | F17: =VLOOKUP(D17,'Master Data'!A:F,4,FALSE) -> m | G17: =VLOOKUP(D17,'Master Data'!A:F,5,FALSE) -> Normal | I17: X | J17: X | M17: x
A18: =VLOOKUP(D18,'Master Data'!A:F,2,FALSE) -> Isabel | B18: =VLOOKUP(D18,'Master Data'!A:F,3,FALSE) -> Reiss | C18: =VLOOKUP(D18,'Master Data'!A:F,6,FALSE) -> Isabelreiss@gmx.de | D18: 00491742016011 | F18: =VLOOKUP(D18,'Master Data'!A:F,4,FALSE) -> w | G18: =VLOOKUP(D18,'Master Data'!A:F,5,FALSE) -> Normal | H18: 190 | I18: X | J18: X | M18: x
A19: =VLOOKUP(D19,'Master Data'!A:F,2,FALSE) -> Sven | B19: =VLOOKUP(D19,'Master Data'!A:F,3,FALSE) -> Hopf | C19: =VLOOKUP(D19,'Master Data'!A:F,6,FALSE) -> svenhopf@hotmail.com | D19: 0795325644 | F19: =VLOOKUP(D19,'Master Data'!A:F,4,FALSE) -> m | G19: =VLOOKUP(D19,'Master Data'!A:F,5,FALSE) -> Normal | H19: 190 | I19: X | J19: X | M19: x
A20: =VLOOKUP(D20,'Master Data'!A:F,2,FALSE) -> Johanna | B20: =VLOOKUP(D20,'Master Data'!A:F,3,FALSE) -> Hoffmann | C20: =VLOOKUP(D20,'Master Data'!A:F,6,FALSE) -> johanna-hoffmann@outlook.com | D20: 0789094058 | F20: =VLOOKUP(D20,'Master Data'!A:F,4,FALSE) -> w | G20: =VLOOKUP(D20,'Master Data'!A:F,5,FALSE) -> Normal | H20: 190 | I20: X | J20: X | M20: x | O20: -
A21: =VLOOKUP(D21,'Master Data'!A:F,2,FALSE) -> Manuela | B21: =VLOOKUP(D21,'Master Data'!A:F,3,FALSE) -> Heymoz | C21: =VLOOKUP(D21,'Master Data'!A:F,6,FALSE) -> m.heymoz@gmx.ch | D21: 0764262929 | F21: =VLOOKUP(D21,'Master Data'!A:F,4,FALSE) -> w | G21: =VLOOKUP(D21,'Master Data'!A:F,5,FALSE) -> Normal | H21: 190 | I21: X | J21: X | K21: - | M21: x
A22: =VLOOKUP(D22,'Master Data'!A:F,2,FALSE) -> Ivan | B22: =VLOOKUP(D22,'Master Data'!A:F,3,FALSE) -> Zuparic | C22: =VLOOKUP(D22,'Master Data'!A:F,6,FALSE) -> ivan.zuparic@gmx.ch | D22: 0793691732 | E22: 2. Kurse | F22: =VLOOKUP(D22,'Master Data'!A:F,4,FALSE) -> m | G22: =VLOOKUP(D22,'Master Data'!A:F,5,FALSE) -> Normal | H22: 285 | I22: - | J22: X | M22: - | N22: - | P22: -
A23: =VLOOKUP(D23,'Master Data'!A:F,2,FALSE) -> Marco Alessandro | B23: =VLOOKUP(D23,'Master Data'!A:F,3,FALSE) -> Pedrazzoli | C23: =VLOOKUP(D23,'Master Data'!A:F,6,FALSE) -> pedrazzolimarco07@gmail.com | D23: 0795764947 | E23: 2. Kurse | F23: =VLOOKUP(D23,'Master Data'!A:F,4,FALSE) -> m | G23: =VLOOKUP(D23,'Master Data'!A:F,5,FALSE) -> Normal | I23: X | J23: X | M23: x
A24: =VLOOKUP(D24,'Master Data'!A:F,2,FALSE) -> Iryna | B24: =VLOOKUP(D24,'Master Data'!A:F,3,FALSE) -> Marrini | C24: =VLOOKUP(D24,'Master Data'!A:F,6,FALSE) -> iryna@marrini.com | D24: 0772655009 | E24: Salsaflow Pass | F24: =VLOOKUP(D24,'Master Data'!A:F,4,FALSE) -> w | G24: =VLOOKUP(D24,'Master Data'!A:F,5,FALSE) -> Normal | I24: X | J24: X | M24: x
A25: =VLOOKUP(D25,'Master Data'!A:F,2,FALSE) -> Nikola | B25: =VLOOKUP(D25,'Master Data'!A:F,3,FALSE) -> Jevtic | C25: =VLOOKUP(D25,'Master Data'!A:F,6,FALSE) -> nikola.jevtic@bluewin.ch | D25: 0796971944 | F25: =VLOOKUP(D25,'Master Data'!A:F,4,FALSE) -> m | G25: =VLOOKUP(D25,'Master Data'!A:F,5,FALSE) -> Normal | I25: X | J25: - | M25: x
A26: =VLOOKUP(D26,'Master Data'!A:F,2,FALSE) -> Ivan | B26: =VLOOKUP(D26,'Master Data'!A:F,3,FALSE) -> Glushenkov | C26: =VLOOKUP(D26,'Master Data'!A:F,6,FALSE) -> ivan.glushenkov.data@gmail.com | D26: 0762636496 | E26: Salsaflow Pass | F26: =VLOOKUP(D26,'Master Data'!A:F,4,FALSE) -> m | G26: =VLOOKUP(D26,'Master Data'!A:F,5,FALSE) -> Normal | I26: X | J26: X | M26: x
A27: =VLOOKUP(D27,'Master Data'!A:F,2,FALSE) -> Burak | B27: =VLOOKUP(D27,'Master Data'!A:F,3,FALSE) -> Yildirim | C27: =VLOOKUP(D27,'Master Data'!A:F,6,FALSE) -> burak.yildirim@gmx.ch | D27: 0795584011 | F27: =VLOOKUP(D27,'Master Data'!A:F,4,FALSE) -> m | G27: =VLOOKUP(D27,'Master Data'!A:F,5,FALSE) -> Normal | I27: - | J27: X | M27: x
A28: =VLOOKUP(D28,'Master Data'!A:F,2,FALSE) -> Yael | B28: =VLOOKUP(D28,'Master Data'!A:F,3,FALSE) -> Hofmann | C28: =VLOOKUP(D28,'Master Data'!A:F,6,FALSE) -> yael_hofmann@hotmail.com | D28: 0794000823 | F28: =VLOOKUP(D28,'Master Data'!A:F,4,FALSE) -> w | G28: =VLOOKUP(D28,'Master Data'!A:F,5,FALSE) -> Student | H28: 190 | I28: X | J28: X | K28: - | L28: - | M28: x
A29: =VLOOKUP(D29,'Master Data'!A:F,2,FALSE) -> Haimo | B29: =VLOOKUP(D29,'Master Data'!A:F,3,FALSE) -> Jöhri | C29: =VLOOKUP(D29,'Master Data'!A:F,6,FALSE) -> paps1408@gmail.com | D29: 0763662642 | F29: =VLOOKUP(D29,'Master Data'!A:F,4,FALSE) -> m | G29: =VLOOKUP(D29,'Master Data'!A:F,5,FALSE) -> Normal | I29: X | J29: X | M29: x | P29: -
A30: =VLOOKUP(D30,'Master Data'!A:F,2,FALSE) -> Jonhattan | B30: =VLOOKUP(D30,'Master Data'!A:F,3,FALSE) -> da Luz | C30: =VLOOKUP(D30,'Master Data'!A:F,6,FALSE) -> jon.daluz@gmail.com | D30: 004915141395445 | F30: =VLOOKUP(D30,'Master Data'!A:F,4,FALSE) -> m | G30: =VLOOKUP(D30,'Master Data'!A:F,5,FALSE) -> Normal | I30: X | J30: X | K30: - | M30: x | O30: -
A31: =VLOOKUP(D31,'Master Data'!A:F,2,FALSE) -> Jill | B31: =VLOOKUP(D31,'Master Data'!A:F,3,FALSE) -> Hoffmann | C31: =VLOOKUP(D31,'Master Data'!A:F,6,FALSE) -> jill.hoffmann@bluewin.ch | D31: 0798730344 | F31: =VLOOKUP(D31,'Master Data'!A:F,4,FALSE) -> w | G31: =VLOOKUP(D31,'Master Data'!A:F,5,FALSE) -> Normal | H31: 190 | I31: X | J31: X | M31: -
A32: =VLOOKUP(D32,'Master Data'!A:F,2,FALSE) -> Leonie | B32: =VLOOKUP(D32,'Master Data'!A:F,3,FALSE) -> Baur | C32: =VLOOKUP(D32,'Master Data'!A:F,6,FALSE) -> leoniebaur@gmx.de | D32: 004915128752067 | F32: =VLOOKUP(D32,'Master Data'!A:F,4,FALSE) -> w | G32: =VLOOKUP(D32,'Master Data'!A:F,5,FALSE) -> Normal | H32: 190 | I32: X | J32: X | M32: x | P32: -
A33: =VLOOKUP(D33,'Master Data'!A:F,2,FALSE) -> Estelle | B33: =VLOOKUP(D33,'Master Data'!A:F,3,FALSE) -> Pierrot | C33: =VLOOKUP(D33,'Master Data'!A:F,6,FALSE) -> stella110@hotmail.fr | D33: 0765235926 | F33: =VLOOKUP(D33,'Master Data'!A:F,4,FALSE) -> w | G33: =VLOOKUP(D33,'Master Data'!A:F,5,FALSE) -> Normal | I33: X | J33: X | M33: x
A34: =VLOOKUP(D34,'Master Data'!A:F,2,FALSE) -> #N/A | B34: =VLOOKUP(D34,'Master Data'!A:F,3,FALSE) -> #N/A | C34: =VLOOKUP(D34,'Master Data'!A:F,5,FALSE) -> #N/A | G34: Einnahmen | H34: =SUM(H7:H33) -> 2948

Sheet Mo_Salsa Beginner Stufe 2
A1: Anmeldungen - Salsa Beginner Stufe 2
A3: Datum: | B3: 05.01.2026 - 02.03.2026 | D3: Kurstag: | E3: Montag | G3: Lehrer: | H3: John
A4: Zeit: | B4: 19:30 - 20:30 | D4: Ort: | E4: Elisabethenanlage 7 | G4: Preis: | H4: CHF 190.- / CHF 160.-
A6: Vorname | B6: Name | C6: E-Mail | D6: Mobile | E6: Bemerkungen | F6: m/w | G6: Tarif | H6: Betrag | I6: Anwesenheit
A7: =VLOOKUP(D7,'Master Data'!A:F,2,FALSE) -> Maria | B7: =VLOOKUP(D7,'Master Data'!A:F,3,FALSE) -> Tapken | C7: =VLOOKUP(D7,'Master Data'!A:F,6,FALSE) -> tapkenmj@gmail.com | D7: 004915168467107 | F7: =VLOOKUP(D7,'Master Data'!A:F,4,FALSE) -> w | G7: =VLOOKUP(D7,'Master Data'!A:F,5,FALSE) -> Normal | H7: 190 | J7: X | M7: -
A8: =VLOOKUP(D8,'Master Data'!A:F,2,FALSE) -> Ben | B8: =VLOOKUP(D8,'Master Data'!A:F,3,FALSE) -> Böke | C8: =VLOOKUP(D8,'Master Data'!A:F,6,FALSE) -> ben25boeke@gmail.com | D8: 00491602122888 | E8: Salsaflow Pass | F8: =VLOOKUP(D8,'Master Data'!A:F,4,FALSE) -> m | G8: =VLOOKUP(D8,'Master Data'!A:F,5,FALSE) -> Normal | J8: X | M8: X
A9: =VLOOKUP(D9,'Master Data'!A:F,2,FALSE) -> Daniel | B9: =VLOOKUP(D9,'Master Data'!A:F,3,FALSE) -> Gysi | C9: =VLOOKUP(D9,'Master Data'!A:F,6,FALSE) -> ehcb.daniel@hotmail.com | D9: 0774037180 | F9: =VLOOKUP(D9,'Master Data'!A:F,4,FALSE) -> m | G9: =VLOOKUP(D9,'Master Data'!A:F,5,FALSE) -> Normal | H9: 135 | I9: X | J9: X | M9: X | N9: - | O9: -
A10: =VLOOKUP(D10,'Master Data'!A:F,2,FALSE) -> Lea | B10: =VLOOKUP(D10,'Master Data'!A:F,3,FALSE) -> Jurisic | C10: =VLOOKUP(D10,'Master Data'!A:F,6,FALSE) -> jurisic_lea@hotmail.com | D10: 0766811821 | F10: =VLOOKUP(D10,'Master Data'!A:F,4,FALSE) -> w | G10: =VLOOKUP(D10,'Master Data'!A:F,5,FALSE) -> Normal | H10: 135 | I10: X | J10: X | M10: X | O10: -
A11: =VLOOKUP(D11,'Master Data'!A:F,2,FALSE) -> Alex | B11: =VLOOKUP(D11,'Master Data'!A:F,3,FALSE) -> Carol Camprecios | C11: =VLOOKUP(D11,'Master Data'!A:F,6,FALSE) -> picard150@gmail.com | D11: 0762007485 | F11: =VLOOKUP(D11,'Master Data'!A:F,4,FALSE) -> m | G11: =VLOOKUP(D11,'Master Data'!A:F,5,FALSE) -> Normal | H11: 100 | I11: X | J11: - | M11: - | N11: - | O11: - | P11: -
A12: =VLOOKUP(D12,'Master Data'!A:F,2,FALSE) -> Marija | B12: =VLOOKUP(D12,'Master Data'!A:F,3,FALSE) -> Milenkovic | C12: =VLOOKUP(D12,'Master Data'!A:F,6,FALSE) -> marijamilenkovic7@hotmail.com | D12: 0788325297 | E12: Salsaflow Pass | F12: =VLOOKUP(D12,'Master Data'!A:F,4,FALSE) -> w | G12: =VLOOKUP(D12,'Master Data'!A:F,5,FALSE) -> Normal | J12: X | M12: X | N12: - | O12: -
A13: =VLOOKUP(D13,'Master Data'!A:F,2,FALSE) -> Sina Maria | B13: =VLOOKUP(D13,'Master Data'!A:F,3,FALSE) -> Schurban | C13: =VLOOKUP(D13,'Master Data'!A:F,6,FALSE) -> sina.schurban@gmx.de | D13: 00491639821908 | F13: =VLOOKUP(D13,'Master Data'!A:F,4,FALSE) -> w | G13: =VLOOKUP(D13,'Master Data'!A:F,5,FALSE) -> Normal | H13: 160 | J13: X | K13: - | M13: X
A14: =VLOOKUP(D14,'Master Data'!A:F,2,FALSE) -> Helena | B14: =VLOOKUP(D14,'Master Data'!A:F,3,FALSE) -> Gens | C14: =VLOOKUP(D14,'Master Data'!A:F,6,FALSE) -> helena.cgens@gmail.com | D14: 0784454023 | E14: halber Kurs | F14: =VLOOKUP(D14,'Master Data'!A:F,4,FALSE) -> w | G14: =VLOOKUP(D14,'Master Data'!A:F,5,FALSE) -> Normal | H14: 95 | I14: - | J14: - | K14: - | L14: X | M14: X | N14: X | O14: X | P14: -
A15: =VLOOKUP(D15,'Master Data'!A:F,2,FALSE) -> Meral | B15: =VLOOKUP(D15,'Master Data'!A:F,3,FALSE) -> Bozkiraç | C15: =VLOOKUP(D15,'Master Data'!A:F,6,FALSE) -> meral.bozkirac@gmail.com | D15: 0783342600 | E15: 2. Kurse | F15: =VLOOKUP(D15,'Master Data'!A:F,4,FALSE) -> w | G15: =VLOOKUP(D15,'Master Data'!A:F,5,FALSE) -> Normal | H15: 95 | J15: X | M15: -
A16: =VLOOKUP(D16,'Master Data'!A:F,2,FALSE) -> Paul | B16: =VLOOKUP(D16,'Master Data'!A:F,3,FALSE) -> Geser | C16: =VLOOKUP(D16,'Master Data'!A:F,6,FALSE) -> paul.geser03@gmail.com | D16: 0796023990 | F16: =VLOOKUP(D16,'Master Data'!A:F,4,FALSE) -> m | G16: =VLOOKUP(D16,'Master Data'!A:F,5,FALSE) -> Paar | H16: 135 | I16: X | J16: X | M16: - | N16: -
A17: =VLOOKUP(D17,'Master Data'!A:F,2,FALSE) -> Raquel | B17: =VLOOKUP(D17,'Master Data'!A:F,3,FALSE) -> Lima | C17: =VLOOKUP(D17,'Master Data'!A:F,6,FALSE) -> rrlima.raquel@gmail.com | D17: 0786682455 | F17: =VLOOKUP(D17,'Master Data'!A:F,4,FALSE) -> w | G17: =VLOOKUP(D17,'Master Data'!A:F,5,FALSE) -> Paar | H17: 135 | I17: X | J17: X | M17: - | N17: -
A18: =VLOOKUP(D18,'Master Data'!A:F,2,FALSE) -> Simon | B18: =VLOOKUP(D18,'Master Data'!A:F,3,FALSE) -> Amstutz | C18: =VLOOKUP(D18,'Master Data'!A:F,6,FALSE) -> simonamstutz96@gmail.com | D18: 0794515889 | F18: =VLOOKUP(D18,'Master Data'!A:F,4,FALSE) -> m | G18: =VLOOKUP(D18,'Master Data'!A:F,5,FALSE) -> Paar | H18: 80 | I18: X | J18: X | M18: X
A19: =VLOOKUP(D19,'Master Data'!A:F,2,FALSE) -> Paloma | B19: =VLOOKUP(D19,'Master Data'!A:F,3,FALSE) -> Castillo Espinoza | C19: =VLOOKUP(D19,'Master Data'!A:F,6,FALSE) -> paloma.castillo@hotmail.com | D19: 0767434494 | F19: =VLOOKUP(D19,'Master Data'!A:F,4,FALSE) -> w | G19: =VLOOKUP(D19,'Master Data'!A:F,5,FALSE) -> Paar | H19: 80 | I19: X | J19: X | M19: -
A20: =VLOOKUP(D20,'Master Data'!A:F,2,FALSE) -> Suelem | B20: =VLOOKUP(D20,'Master Data'!A:F,3,FALSE) -> Izidoro | C20: =VLOOKUP(D20,'Master Data'!A:F,6,FALSE) -> suelem.izidoro@gmx.com | D20: 0798749914 | F20: =VLOOKUP(D20,'Master Data'!A:F,4,FALSE) -> w | G20: =VLOOKUP(D20,'Master Data'!A:F,5,FALSE) -> Normal | H20: 190 | I20: X | J20: X | M20: X
A21: =VLOOKUP(D21,'Master Data'!A:F,2,FALSE) -> Ani | B21: =VLOOKUP(D21,'Master Data'!A:F,3,FALSE) -> Rukhadze | C21: =VLOOKUP(D21,'Master Data'!A:F,6,FALSE) -> ani_rukhadze@yahoo.com | D21: 0767497456 | F21: w | G21: Normal | H21: 190 | I21: X | J21: X | M21: X
A22: =VLOOKUP(D22,'Master Data'!A:F,2,FALSE) -> Valentina | B22: =VLOOKUP(D22,'Master Data'!A:F,3,FALSE) -> Rodriguez | C22: =VLOOKUP(D22,'Master Data'!A:F,6,FALSE) -> valentina.rezia@bluewin.ch | D22: 0799573945 | F22: =VLOOKUP(D22,'Master Data'!A:F,4,FALSE) -> w | G22: =VLOOKUP(D22,'Master Data'!A:F,5,FALSE) -> Paar | H22: 160 | I22: X | J22: X | M22: X
A23: =VLOOKUP(D23,'Master Data'!A:F,2,FALSE) -> Javier | B23: =VLOOKUP(D23,'Master Data'!A:F,3,FALSE) -> Rodriguez | C23: =VLOOKUP(D23,'Master Data'!A:F,6,FALSE) -> jjrv1987@hotmail.com | D23: 0764202316 | F23: =VLOOKUP(D23,'Master Data'!A:F,4,FALSE) -> m | G23: =VLOOKUP(D23,'Master Data'!A:F,5,FALSE) -> Paar | H23: 160 | I23: X | J23: X | L23: - | M23: X | N23: -
A24: =VLOOKUP(D24,'Master Data'!A:F,2,FALSE) -> Bülent | B24: =VLOOKUP(D24,'Master Data'!A:F,3,FALSE) -> Ekinci | C24: =VLOOKUP(D24,'Master Data'!A:F,6,FALSE) -> buelentekinci24@gamil.com | D24: 00491637919721 | E24: Salsaflow Pass | F24: =VLOOKUP(D24,'Master Data'!A:F,4,FALSE) -> m | G24: =VLOOKUP(D24,'Master Data'!A:F,5,FALSE) -> Normal | I24: X | J24: X | M24: X
A25: =VLOOKUP(D25,'Master Data'!A:F,2,FALSE) -> David | B25: =VLOOKUP(D25,'Master Data'!A:F,3,FALSE) -> Schwegler | C25: =VLOOKUP(D25,'Master Data'!A:F,6,FALSE) -> davidschweg@gmail.com | D25: 0774907360 | F25: =VLOOKUP(D25,'Master Data'!A:F,4,FALSE) -> m | G25: =VLOOKUP(D25,'Master Data'!A:F,5,FALSE) -> Normal | M25: X
A26: =VLOOKUP(D26,'Master Data'!A:F,2,FALSE) -> #N/A | B26: =VLOOKUP(D26,'Master Data'!A:F,3,FALSE) -> #N/A | C26: =VLOOKUP(D26,'Master Data'!A:F,6,FALSE) -> #N/A | F26: =VLOOKUP(D26,'Master Data'!A:F,4,FALSE) -> #N/A | G26: =VLOOKUP(D26,'Master Data'!A:F,5,FALSE) -> #N/A
A27: =VLOOKUP(D27,'Master Data'!A:F,2,FALSE) -> #N/A | B27: =VLOOKUP(D27,'Master Data'!A:F,3,FALSE) -> #N/A | C27: =VLOOKUP(D27,'Master Data'!A:F,6,FALSE) -> #N/A | F27: =VLOOKUP(D27,'Master Data'!A:F,4,FALSE) -> #N/A | G27: =VLOOKUP(D27,'Master Data'!A:F,5,FALSE) -> #N/A
A28: =VLOOKUP(D28,'Master Data'!A:F,2,FALSE) -> #N/A | B28: =VLOOKUP(D28,'Master Data'!A:F,3,FALSE) -> #N/A | C28: =VLOOKUP(D28,'Master Data'!A:F,6,FALSE) -> #N/A | F28: =VLOOKUP(D28,'Master Data'!A:F,4,FALSE) -> #N/A | G28: =VLOOKUP(D28,'Master Data'!A:F,5,FALSE) -> #N/A
A29: =VLOOKUP(D29,'Master Data'!A:F,2,FALSE) -> #N/A | B29: =VLOOKUP(D29,'Master Data'!A:F,3,FALSE) -> #N/A | C29: =VLOOKUP(D29,'Master Data'!A:F,6,FALSE) -> #N/A | F29: =VLOOKUP(D29,'Master Data'!A:F,4,FALSE) -> #N/A | G29: =VLOOKUP(D29,'Master Data'!A:F,5,FALSE) -> #N/A
A30: =VLOOKUP(D30,'Master Data'!A:F,2,FALSE) -> #N/A | B30: =VLOOKUP(D30,'Master Data'!A:F,3,FALSE) -> #N/A | C30: =VLOOKUP(D30,'Master Data'!A:F,6,FALSE) -> #N/A | F30: =VLOOKUP(D30,'Master Data'!A:F,4,FALSE) -> #N/A | G30: =VLOOKUP(D30,'Master Data'!A:F,5,FALSE) -> #N/A
A31: =VLOOKUP(D31,'Master Data'!A:F,2,FALSE) -> #N/A | B31: =VLOOKUP(D31,'Master Data'!A:F,3,FALSE) -> #N/A | C31: =VLOOKUP(D31,'Master Data'!A:F,6,FALSE) -> #N/A | F31: =VLOOKUP(D31,'Master Data'!A:F,4,FALSE) -> #N/A | G31: =VLOOKUP(D31,'Master Data'!A:F,5,FALSE) -> #N/A
A32: =VLOOKUP(D32,'Master Data'!A:F,2,FALSE) -> #N/A | B32: =VLOOKUP(D32,'Master Data'!A:F,3,FALSE) -> #N/A | C32: =VLOOKUP(D32,'Master Data'!A:F,5,FALSE) -> #N/A | F32: =VLOOKUP(D32,'Master Data'!A:F,4,FALSE) -> #N/A | G32: =VLOOKUP(D32,'Master Data'!A:F,5,FALSE) -> #N/A | H32: =SUM(H7:H31) -> 2040

Sheet Mo_Salsa Advanced 15
A1: Anmeldungen - Salsa Advanced Stufe 15
A3: Datum: | B3: 05.01.2026 - 02.03.2026 | D3: Kurstag: | E3: Montag | G3: Lehrer: | H3: Viviana & Sebastian
A4: Zeit: | B4: 20:30 - 21:30 | D4: Ort: | E4: Elisabethenanlage 7 | G4: Preis: | H4: CHF 190.- / CHF 160.-
A6: Vorname | B6: Name | C6: E-Mail | D6: Mobile | E6: Bemerkungen | F6: m/w | G6: Tarif | H6: Betrag | I6: Anwesenheit
